Workbook

Sheet Table 1
A1: Name of Work :- Construction of Pipe Distribution Network on Minors along with CADWM from RD 0 to 10000 M on Main Canal of Surewada Lift Irrigation Scheme (Irrigation Potential of 2073 Ha) | W1: Amount AS PER TENDER | X1: Design | Y1: Amount AS PER DESIGN
A2: Name of Item | D2: Unit | E2: Rate | F2: Tender | G2: Design | H2: Tender | I2: Design | J2: Tender | K2: Design | L2: Tender | M2: Design | N2: Tender | O2: Design | P2: Tender | Q2: Design | R2: Tender | S2: Design | T2: Tender | U2: Design | V2: Tender
F3: Injewada Mr @ RD 120 M | H3: Sarpewda Mr @ RD 1110 M | J3: Koka Mr 1 @ RD 3240 M | L3: Koka Mr 2 @ RD 4645 M | N3: Sonkund Mr @ RD 6030 M | P3: Palora Mr @ RD 6850 M | R3: Kesalwada Mr @ RD 8770 M | T3: Dudhara Minor @ RD 1300 m | V3: Total | X3: Total
F4: Qty | G4: Qty | H4: Qty | I4: Qty | J4: Qty | K4: Qty | L4: Qty | M4: Qty | N4: Qty | O4: Qty | P4: Qty | Q4: Qty | R4: Qty | S4: Qty | T4: Qty | U4: Qty | V4: Qty | W4: =+W146/V5 -> 197299.06 | X4: Qty | Y4: =+Y146/X5 -> 171459.68 | AA4: =+Y4*G5 -> 25619505
A5: Area CCA | D5: HA | E5: 0 | F5: 124.95 | G5: 149.42 | H5: 47.611 | I5: 58.72 | J5: 454.04 | K5: 530.14 | L5: 52.19 | M5: 77.92 | N5: 164.88 | O5: 221.79 | P5: 493.502 | Q5: 612.33 | R5: 133.58 | S5: 162.07 | U5: 33.86 | V5: 1470.75 | W5: =+(W25+W27)/V5 -> 114004.67 | X5: =S5+Q5+O5+M5+K5+I5+G5 -> 1812.39 | Y5: =+(Y25+Y27)/X5 -> 99849.389
A6: HDPE 4 Kg /Cm2
A7: a | B7: 110 | C7: mm | D7: Rmt | E7: 329.2 | F7: 884 | G7: 0 | H7: 0 | I7: 0 | J7: 208 | K7: 0 | L7: 0 | M7: 0 | N7: 0 | O7: 0 | P7: 0 | Q7: 0 | R7: 0 | S7: 0 | V7: =R7+P7+N7+L7+J7+H7+F7 -> 1092 | W7: =+V7*$E7 -> 359486.4 | X7: =S7+Q7+O7+M7+K7+I7+G7 -> 0 | Y7: =+X7*$E7 -> 0 | Z7: =+Y7-W7 -> -359486.4 | AA7: =+Z7/W7 -> -1
A8: b | B8: 125 | C8: mm | D8: Rmt | E8: 394.9 | F8: 1542 | G8: 0 | H8: 0 | I8: 0 | J8: 2239 | K8: 0 | L8: 856 | M8: 0 | N8: 0 | O8: 0 | P8: 0 | Q8: 0 | R8: 0 | S8: 0 | V8: =R8+P8+N8+L8+J8+H8+F8 -> 4637 | W8: =+V8*$E8 -> 1831151.3 | X8: =S8+Q8+O8+M8+K8+I8+G8 -> 0 | Y8: =+X8*$E8 -> 0 | Z8: =+Y8-W8 -> -1831151.3 | AA8: =+Z8/W8 -> -1
A9: c | B9: 140 | C9: mm | D9: Rmt | E9: 487.35 | F9: 327 | G9: 1291.3 | H9: 476 | I9: 1216 | J9: 4731 | K9: 6810 | L9: 447 | M9: 1587 | N9: 3205 | O9: 2527 | P9: 6659 | Q9: 7194 | R9: 586 | S9: 1827 | U9: 112 | V9: =R9+P9+N9+L9+J9+H9+F9 -> 16431 | W9: =+V9*$E9 -> 8007647.9 | X9: =S9+Q9+O9+M9+K9+I9+G9 -> 22452.3 | Y9: =+X9*$E9 -> 10942128 | Z9: =+Y9-W9 -> 2934480.6 | AA9: =+Z9/W9 -> 0.36645974
A10: d | B10: 160 | C10: mm | D10: Rmt | E10: 616.95 | F10: 664 | G10: 383.03 | H10: 888 | I10: 0 | J10: 780 | K10: 1458 | L10: 0 | M10: 0 | N10: 944 | O10: 705 | P10: 589 | Q10: 919 | R10: 1324 | S10: 866 | U10: 297 | V10: =R10+P10+N10+L10+J10+H10+F10 -> 5189 | W10: =+V10*$E10 -> 3201353.6 | X10: =S10+Q10+O10+M10+K10+I10+G10 -> 4331.03 | Y10: =+X10*$E10 -> 2672029 | Z10: =+Y10-W10 -> -529324.59 | AA10: =+Z10/W10 -> -0.165344
A11: e | B11: 180 | C11: mm | D11: Rmt | E11: 757.95 | F11: 1043 | G11: 610.01 | H11: 465 | I11: 0 | J11: 993 | K11: 1336 | L11: 322 | M11: 0 | N11: 350 | O11: 227 | P11: 529 | Q11: 1712 | R11: 109 | S11: 200 | V11: =R11+P11+N11+L11+J11+H11+F11 -> 3811 | W11: =+V11*$E11 -> 2888547.5 | X11: =S11+Q11+O11+M11+K11+I11+G11 -> 4085.01 | Y11: =+X11*$E11 -> 3096233.3 | Z11: =+Y11-W11 -> 207685.88 | AA11: =+Z11/W11 -> 0.071899764
A12: f | B12: 200 | C12: mm | D12: Rmt | E12: 922.4 | F12: 836 | G12: 417.52 | H12: 0 | I12: 355 | J12: 0 | K12: 583 | L12: 0 | M12: 94 | N12: 287 | O12: 1250 | P12: 591 | Q12: 824 | R12: 169 | S12: 461 | U12: 10 | V12: =R12+P12+N12+L12+J12+H12+F12 -> 1883 | W12: =+V12*$E12 -> 1736879.2 | X12: =S12+Q12+O12+M12+K12+I12+G12 -> 3984.52 | Y12: =+X12*$E12 -> 3675321.2 | Z12: =+Y12-W12 -> 1938442 | AA12: =+Z12/W12 -> 1.1160489
A13: g | B13: 225 | C13: mm | D13: Rmt | E13: 1171 | F13: 264 | G13: 114.35 | H13: 0 | I13: 90 | J13: 484 | K13: 720 | L13: 0 | M13: 0 | N13: 0 | O13: 584 | P13: 1272 | Q13: 1360 | R13: 822 | S13: 0 | U13: 609 | V13: =R13+P13+N13+L13+J13+H13+F13 -> 2842 | W13: =+V13*$E13 -> 3327982 | X13: =S13+Q13+O13+M13+K13+I13+G13 -> 2868.35 | Y13: =+X13*$E13 -> 3358837.9 | Z13: =+Y13-W13 -> 30855.85 | AA13: =+Z13/W13 -> 0.0092716397
A14: h | B14: 250 | C14: mm | D14: Rmt | E14: 1411.8 | F14: 175 | G14: 133.37 | H14: 0 | I14: 472 | J14: 127 | K14: 478 | L14: 219 | M14: 211 | N14: 0 | O14: 236 | P14: 860 | Q14: 635 | R14: 144 | S14: 299 | V14: =R14+P14+N14+L14+J14+H14+F14 -> 1525 | W14: =+V14*$E14 -> 2152995 | X14: =S14+Q14+O14+M14+K14+I14+G14 -> 2464.37 | Y14: =+X14*$E14 -> 3479197.6 | Z14: =+Y14-W14 -> 1326202.6 | AA14: =+Z14/W14 -> 0.61598033
A15: i | B15: 280 | C15: mm | D15: Rmt | E15: 1762.25 | F15: 232 | G15: 1008.39 | H15: 313 | I15: 0 | J15: 439 | K15: 388 | L15: 140 | M15: 232 | N15: 235 | O15: 0 | P15: 1040 | Q15: 744 | R15: 0 | S15: 237 | U15: 371 | V15: =R15+P15+N15+L15+J15+H15+F15 -> 2399 | W15: =+V15*$E15 -> 4227637.8 | X15: =S15+Q15+O15+M15+K15+I15+G15 -> 2609.39 | Y15: =+X15*$E15 -> 4598397.5 | Z15: =+Y15-W15 -> 370759.78 | AA15: =+Z15/W15 -> 0.087699041
A16: j | B16: 315 | C16: mm | D16: Rmt | E16: 2218.75 | F16: 0 | G16: 0 | H16: 0 | I16: 268 | J16: 348 | K16: 169 | L16: 609 | M16: 168 | N16: 0 | O16: 184 | P16: 1429 | Q16: 1640 | R16: 123 | S16: 0 | U16: 19 | V16: =R16+P16+N16+L16+J16+H16+F16 -> 2509 | W16: =+V16*$E16 -> 5566843.8 | X16: =S16+Q16+O16+M16+K16+I16+G16 -> 2429 | Y16: =+X16*$E16 -> 5389343.8 | Z16: =+Y16-W16 -> -177500 | AA16: =+Z16/W16 -> -0.031885213
A17: k | B17: 355 | C17: mm | D17: Rmt | E17: 2779.4 | F17: 380 | G17: 225.7 | H17: 0 | I17: 40 | J17: 557 | K17: 133 | L17: 875 | M17: 282 | N17: 139 | O17: 383 | P17: 244 | Q17: 2215 | R17: 0 | S17: 0 | V17: =R17+P17+N17+L17+J17+H17+F17 -> 2195 | W17: =+V17*$E17 -> 6100783 | X17: =S17+Q17+O17+M17+K17+I17+G17 -> 3278.7 | Y17: =+X17*$E17 -> 9112818.8 | Z17: =+Y17-W17 -> 3012035.8 | AA17: =+Z17/W17 -> 0.49371298
A18: l | B18: 400 | C18: mm | D18: Rmt | E18: 3463.05 | F18: 0 | G18: 0 | H18: 0 | I18: 0 | J18: 905 | K18: 928 | L18: 0 | M18: 843 | N18: 127 | O18: 207 | P18: 550 | Q18: 923 | R18: 476 | S18: 0 | V18: =R18+P18+N18+L18+J18+H18+F18 -> 2058 | W18: =+V18*$E18 -> 7126956.9 | X18: =S18+Q18+O18+M18+K18+I18+G18 -> 2901 | Y18: =+X18*$E18 -> 10046308 | Z18: =+Y18-W18 -> 2919351.2 | AA18: =+Z18/W18 -> 0.40962099
A19: m | B19: 450 | C19: mm | D19: Rmt | E19: 4297.2 | F19: 0 | G19: 141.94 | H19: 0 | I19: 0 | J19: 0 | K19: 165 | L19: 0 | M19: 0 | N19: 329 | O19: 0 | P19: 1005 | Q19: 209 | R19: 0 | S19: 0 | V19: =R19+P19+N19+L19+J19+H19+F19 -> 1334 | W19: =+V19*$E19 -> 5732464.8 | X19: =S19+Q19+O19+M19+K19+I19+G19 -> 515.94 | Y19: =+X19*$E19 -> 2217097.4 | Z19: =+Y19-W19 -> -3515367.4 | AA19: =+Z19/W19 -> -0.61323838
A20: n | B20: 500 | C20: mm | D20: Rmt | E20: 5265.45 | F20: 935 | G20: 517.46 | H20: 0 | I20: 0 | J20: 920 | K20: 259 | L20: 0 | M20: 0 | N20: 0 | O20: 0 | P20: 1527 | Q20: 136 | R20: 289 | S20: 933 | V20: =R20+P20+N20+L20+J20+H20+F20 -> 3671 | W20: =+V20*$E20 -> 19329467 | X20: =S20+Q20+O20+M20+K20+I20+G20 -> 1845.46 | Y20: =+X20*$E20 -> 9717177.4 | Z20: =+Y20-W20 -> -9612289.6 | AA20: =+Z20/W20 -> -0.49728684
A21: o | B21: 560 | C21: mm | D21: Rmt | E21: 6515.7 | F21: 0 | G21: 1366.33 | H21: 0 | I21: 0 | J21: 963 | K21: 920 | L21: 0 | M21: 0 | N21: 0 | O21: 66 | P21: 0 | Q21: 243 | R21: 970 | S21: 174 | V21: =R21+P21+N21+L21+J21+H21+F21 -> 1933 | W21: =+V21*$E21 -> 12594848 | X21: =S21+Q21+O21+M21+K21+I21+G21 -> 2769.33 | Y21: =+X21*$E21 -> 18044123 | Z21: =+Y21-W21 -> 5449275.4 | AA21: =+Z21/W21 -> 0.43265908
A22: p | B22: 630 | C22: mm | D22: Rmt | E22: 8256.05 | F22: 438 | G22: 106.42 | H22: 0 | I22: 0 | J22: 1173 | K22: 1138 | L22: 0 | M22: 0 | N22: 1531 | O22: 681 | P22: 0 | Q22: 516 | R22: 0 | S22: 523 | V22: =R22+P22+N22+L22+J22+H22+F22 -> 3142 | W22: =+V22*$E22 -> 25940509 | X22: =S22+Q22+O22+M22+K22+I22+G22 -> 2964.42 | Y22: =+X22*$E22 -> 24474400 | Z22: =+Y22-W22 -> -1466109.4 | AA22: =+Z22/W22 -> -0.056518141
A23: q | B23: 710 | C23: mm | D23: Rmt | E23: 10397.35 | F23: 0 | G23: 0 | H23: 0 | I23: 0 | J23: 1537 | K23: 1325 | L23: 0 | M23: 0 | N23: 0 | O23: 638 | P23: 0 | Q23: 522 | R23: 615 | S23: 182 | V23: =R23+P23+N23+L23+J23+H23+F23 -> 2152 | W23: =+V23*$E23 -> 22375097 | X23: =S23+Q23+O23+M23+K23+I23+G23 -> 2667 | Y23: =+X23*$E23 -> 27729732 | Z23: =+Y23-W23 -> 5354635.2 | AA23: =+Z23/W23 -> 0.23931227
A24: r | B24: 800 | C24: mm | D24: Rmt | E24: 12273.5 | F24: 0 | G24: 0 | H24: 0 | I24: 0 | J24: 523 | K24: 1045 | L24: 0 | M24: 0 | N24: 0 | O24: 0 | P24: 539 | Q24: 1160 | R24: 0 | S24: 0 | V24: =R24+P24+N24+L24+J24+H24+F24 -> 1062 | W24: =+V24*$E24 -> 13034457 | X24: =S24+Q24+O24+M24+K24+I24+G24 -> 2205 | Y24: =+X24*$E24 -> 27063068 | Z24: =+Y24-W24 -> 14028610 | AA24: =+Z24/W24 -> 1.0762712
A25: PCCP | F25: =SUM(F7:F24) -> 7720 | G25: =SUM(G7:G24) -> 6315.82 | H25: =SUM(H7:H24) -> 2142 | I25: =SUM(I7:I24) -> 2441 | J25: =SUM(J7:J24) -> 16927 | K25: =SUM(K7:K24) -> 17855 | L25: =SUM(L7:L24) -> 3468 | M25: =SUM(M7:M24) -> 3417 | ... Y25: =SUM(Y7:Y24) -> 1.6561621e+08 | Z25: =Y25-W25 -> 20081106 | AA25: =+Z25/W25 -> 0.13798118 | AC25: =+X25-V25 -> 4505.82 | AD25: =+AC25/V25 -> 0.075266349
A26: Item No. 8:- Providing and supplying Prestressed Concrete Cylinder Pipes suitable for sliding ovrelap | W26: =+W25/V25 -> 2431.055 | Y26: =+Y25/X25 -> 2572.8461
A27: a | B27: 900 | C27: mm | D27: Rmt | E27: 14199.65 | F27: 0 | H27: 0 | J27: 716 | K27: 516 | L27: 0 | N27: 0 | P27: 843 | Q27: 565 | R27: 0 | V27: =R27+P27+N27+L27+J27+H27+F27 -> 1559 | W27: =+V27*$E27 -> 22137254 | X27: =S27+Q27+O27+M27+K27+I27+G27 -> 1081 | Y27: =+X27*$E27 -> 15349822 | Z27: =Y27-W27 -> -6787432.7 | AA27: =+Z27/W27 -> -0.3066068
A28: ITEM NO :1A Excavation for deep trenches for laying rising | D28: CUM | E28: 158.5 | F28: =+SUM([1]Wetted!$G$5:$G$6) -> 11716.26 | G28: =+SUM([2]Wetted!G5:G6) -> 11513.82 | H28: =+SUM([1]Wetted!$J$5:$J$6) -> 2671.12 | I28: =+SUM([2]Wetted!$J$5:$J$6) -> 3087.36 | J28: =+SUM([1]Wetted!$M$5:$M$6) -> 32587.49 | K28: =+SUM([2]Wetted!$M$5:$M$6) -> 31295.64 | L28: =+SUM([1]Wetted!$P$5:$P$6) -> 4417.09 | M28: =+SUM([2]Wetted!$P$5:$P$6) -> 4366.43 | N28: =+SUM([1]Wetted!$S$5:$S$6) -> 10505.78 | O28: =+SUM([2]Wetted!$S$5:$S$6) -> 10805.03 | P28: =+SUM([1]Wetted!$V$5:$V$6) -> 26946.24 | Q28: =+SUM([2]Wetted!$V$5:$V$6) -> 33610.38 | R28: =+SUM([1]Wetted!$Y$5:$Y$6) -> 9185.58 | S28: =+SUM([2]Wetted!$Y$5:$Y$6) -> 7924.08 | V28: =R28+P28+N28+L28+J28+H28+F28 -> 98029.56 | W28: =+V28*$E28 -> 15537685 | X28: =S28+Q28+O28+M28+K28+I28+G28 -> 102602.74 | Y28: =+X28*$E28 -> 16262534 | Z28: =Y28-W28 -> 724849.03
A29: ITEM NO : 1B EXCAVATION FOR DEEP TRENCHES | D29: CUM | E29: 647.9 | F29: =+[1]Wetted!$G$8 -> 1301.81 | G29: =+[2]Wetted!$G$8 -> 1279.31 | H29: =+[1]Wetted!$J$8 -> 425.82 | I29: =+[2]Wetted!$J$8 -> 492.19 | J29: =+[1]Wetted!$M$8 -> 3620.83 | K29: =+[2]Wetted!$M$8 -> 3477.29 | L29: =+[1]Wetted!$P$8 -> 490.79 | M29: =+[2]Wetted!$P$8 -> 485.15 | N29: =+[1]Wetted!$S$8 -> 1167.31 | O29: =+[2]Wetted!$S$8 -> 1200.55 | P29: =+[1]Wetted!$V$8 -> 2994.03 | Q29: =+[2]Wetted!$V$8 -> 3734.48 | R29: =+[1]Wetted!$Y$8 -> 1464.36 | S29: =+[2]Wetted!$Y$8 -> 1263.25 | V29: =R29+P29+N29+L29+J29+H29+F29 -> 11464.95 | W29: =+V29*$E29 -> 7428141.1 | X29: =S29+Q29+O29+M29+K29+I29+G29 -> 11932.22 | Y29: =+X29*$E29 -> 7730885.3 | Z29: =Y29-W29 -> 302744.23
A30: ITEM NO :2 EXCAVATION IN SOFT STARTA | D30: CUM | E30: 106 | F30: =+SUM([1]Wetted!$G$9:$G$10) -> 440.25 | G30: =+SUM([2]Wetted!$G$9:$G$10) -> 440.25 | H30: =+SUM([1]Wetted!$J$9:$J$10) -> 173.95 | I30: =+SUM([2]Wetted!$J$9:$J$10) -> 173.95 | J30: =+SUM([1]Wetted!$M$9:$M$10) -> 1079.96 | K30: =+SUM([2]Wetted!$M$9:$M$10) -> 1079.96 | L30: =+SUM([1]Wetted!$P$9:$P$10) -> 213.11 | M30: =+SUM([2]Wetted!$P$9:$P$10) -> 213.11 | N30: =+SUM([1]Wetted!$S$9:$S$10) -> 580.13 | O30: =+SUM([2]Wetted!$S$9:$S$10) -> 580.13 | P30: =+SUM([1]Wetted!$V$9:$V$10) -> 1903.3 | Q30: =+SUM([2]Wetted!$V$9:$V$10) -> 1903.3 | R30: =+SUM([1]Wetted!$Y$9:$Y$10) -> 383.6 | S30: =+SUM([2]Wetted!$Y$9:$Y$10) -> 383.6 | V30: =R30+P30+N30+L30+J30+H30+F30 -> 4774.3 | W30: =+V30*$E30 -> 506075.8 | X30: =S30+Q30+O30+M30+K30+I30+G30 -> 4774.3 | Y30: =+X30*$E30 -> 506075.8 | Z30: =Y30-W30 -> 0
A31: ITEM NO :3 MURUM BEDDING | D31: CUM | E31: 242.9 | F31: =+[1]Wetted!$G$13 -> 1232.18 | G31: =+SUM([2]Wetted!$G$13:$G$14) -> 1162.29 | H31: =+[1]Wetted!$J$13 -> 291.06 | I31: =+SUM([2]Wetted!$J$13:$J$14) -> 344.91 | J31: =+[1]Wetted!$M$13 -> 3475.72 | K31: =+SUM([2]Wetted!$M$13:$M$14) -> 3357.1 | L31: =+[1]Wetted!$P$13 -> 548.26 | M31: =+SUM([2]Wetted!$P$13:$P$14) -> 541.6 | N31: =+[1]Wetted!$S$13 -> 1236.26 | O31: =+SUM([2]Wetted!$S$13:$S$14) -> 1303.58 | P31: =+[1]Wetted!$V$13 -> 3144.86 | Q31: =+SUM([2]Wetted!$V$13:$V$14) -> 3898.66 | R31: =+[1]Wetted!$Y$13 -> 1098.31 | S31: =+SUM([2]Wetted!$Y$13:$Y$140) -> 13766.764 | V31: =R31+P31+N31+L31+J31+H31+F31 -> 11026.65 | W31: =+V31*$E31 -> 2678373.3 | X31: =S31+Q31+O31+M31+K31+I31+G31 -> 24374.904 | Y31: =+X31*$E31 -> 5920664.2 | Z31: =Y31-W31 -> 3242290.9
A32: ITEM NO : 4 BACKFILLING | D32: CUM | E32: 47.3 | F32: =+[1]Wetted!$G16 -> 7454.7312 | G32: =+[2]Wetted!$G16 -> 7315.9052 | H32: =+[1]Wetted!$J16 -> 1751.4 | I32: =+[2]Wetted!$J16 -> 2011.47 | J32: =+[1]Wetted!$M16 -> 19744.877 | K32: =+[2]Wetted!$M16 -> 19011.946 | L32: =+[1]Wetted!$P16 -> 2633.8249 | M32: =+[2]Wetted!$P16 -> 2603.267 | N32: =+[1]Wetted!$S16 -> 6273.536 | O32: =+[2]Wetted!$S16 -> 6488.7399 | P32: =+[1]Wetted!$V16 -> 16362.96 | Q32: =+[2]Wetted!$V16 -> 20244.75 | R32: =+[1]Wetted!$Y16 -> 5680.3031 | S32: =+[2]Wetted!$Y16 -> 4931.7525 | V32: =R32+P32+N32+L32+J32+H32+F32 -> 59901.632 | W32: =+V32*$E32 -> 2833347.2 | X32: =S32+Q32+O32+M32+K32+I32+G32 -> 62607.831 | Y32: =+X32*$E32 -> 2961350.4 | Z32: =Y32-W32 -> 128003.2
A33: ITEM NO :5 RUBBLE SOLLING BELOW | D33: CUM | E33: 1973 | F33: =+[1]Wetted!$G17 -> 39.94 | G33: =+[2]Wetted!$G17 -> 39.94 | H33: =+[1]Wetted!$J17 -> 20.7 | I33: =+[2]Wetted!$J17 -> 20.7 | J33: =+[1]Wetted!$M17 -> 98.02 | K33: =+[2]Wetted!$M17 -> 98.02 | L33: =+[1]Wetted!$P17 -> 24.74 | M33: =+[2]Wetted!$P17 -> 24.74 | N33: =+[1]Wetted!$S17 -> 58.62 | O33: =+[2]Wetted!$S17 -> 58.62 | P33: =+[1]Wetted!$V17 -> 171.46 | Q33: =+[2]Wetted!$V17 -> 171.46 | R33: =+[1]Wetted!$Y17 -> 41.58 | S33: =+[2]Wetted!$Y17 -> 41.58 | V33: =R33+P33+N33+L33+J33+H33+F33 -> 455.06 | W33: =+V33*$E33 -> 897833.38 | X33: =S33+Q33+O33+M33+K33+I33+G33 -> 455.06 | Y33: =+X33*$E33 -> 897833.38 | Z33: =Y33-W33 -> 0
A34: ITEM NO :6 SAND BEDDING | D34: CUM | E34: 1276.25 | F34: =+[1]Wetted!$G18 -> 364.4 | G34: =+[2]Wetted!$G18 -> 343.14 | H34: =+[1]Wetted!$J18 -> 98.51 | I34: =+[2]Wetted!$J18 -> 111.98 | J34: =+[1]Wetted!$M18 -> 1004.2 | K34: =+[2]Wetted!$M18 -> 974.54 | L34: =+[1]Wetted!$P18 -> 168.75 | M34: =+[2]Wetted!$P18 -> 167.08 | N34: =+[1]Wetted!$S18 -> 382.84 | O34: =+[2]Wetted!$S18 -> 400.93 | P34: =+[1]Wetted!$V18 -> 994.92 | Q34: =+[2]Wetted!$V18 -> 1192.22 | R34: =+[1]Wetted!$Y18 -> 327.52 | S34: =+[2]Wetted!$Y18 -> 298.86 | V34: =R34+P34+N34+L34+J34+H34+F34 -> 3341.14 | W34: =+V34*$E34 -> 4264129.9 | X34: =S34+Q34+O34+M34+K34+I34+G34 -> 3488.75 | Y34: =+X34*$E34 -> 4452517.2 | Z34: =Y34-W34 -> 188387.26
V35: =R35+P35+N35+L35+J35+H35+F35 -> 0 | W35: =+V35*$E35 -> 0 | X35: =S35+Q35+O35+M35+K35+I35+G35 -> 0 | Y35: =+X35*$E35 -> 0 | Z35: =Y35-W35 -> 0
A36: ITEM NO 7 | V36: =R36+P36+N36+L36+J36+H36+F36 -> 0 | W36: =+V36*$E36 -> 0 | X36: =S36+Q36+O36+M36+K36+I36+G36 -> 0 | Y36: =+X36*$E36 -> 0 | Z36: =Y36-W36 -> 0
B37: 110 | C37: mm | D37: Rmt | E37: 329.2 | F37: =+F7 -> 884 | G37: =+G7 -> 0 | H37: =+H7 -> 0 | I37: =+I7 -> 0 | J37: =+J7 -> 208 | K37: =+K7 -> 0 | L37: =+L7 -> 0 | M37: =+M7 -> 0 | ... S37: =+S7 -> 0 | V37: =R37+P37+N37+L37+J37+H37+F37 -> 1092 | W37: =+V37*$E37 -> 359486.4 | X37: =S37+Q37+O37+M37+K37+I37+G37 -> 0 | Y37: =+X37*$E37 -> 0 | Z37: =Y37-W37 -> -359486.4
B38: 125 | C38: mm | D38: Rmt | E38: 394.9 | F38: =+F8 -> 1542 | G38: =+G8 -> 0 | H38: =+H8 -> 0 | I38: =+I8 -> 0 | J38: =+J8 -> 2239 | K38: =+K8 -> 0 | L38: =+L8 -> 856 | M38: =+M8 -> 0 | ... S38: =+S8 -> 0 | V38: =R38+P38+N38+L38+J38+H38+F38 -> 4637 | W38: =+V38*$E38 -> 1831151.3 | X38: =S38+Q38+O38+M38+K38+I38+G38 -> 0 | Y38: =+X38*$E38 -> 0 | Z38: =Y38-W38 -> -1831151.3
B39: 140 | C39: mm | D39: Rmt | E39: 487.35 | F39: =+F9 -> 327 | G39: =+G9 -> 1291.3 | H39: =+H9 -> 476 | I39: =+I9 -> 1216 | J39: =+J9 -> 4731 | K39: =+K9 -> 6810 | L39: =+L9 -> 447 | M39: =+M9 -> 1587 | ... S39: =+S9 -> 1827 | V39: =R39+P39+N39+L39+J39+H39+F39 -> 16431 | W39: =+V39*$E39 -> 8007647.9 | X39: =S39+Q39+O39+M39+K39+I39+G39 -> 22452.3 | Y39: =+X39*$E39 -> 10942128 | Z39: =Y39-W39 -> 2934480.6
B40: 160 | C40: mm | D40: Rmt | E40: 616.95 | F40: =+F10 -> 664 | G40: =+G10 -> 383.03 | H40: =+H10 -> 888 | I40: =+I10 -> 0 | J40: =+J10 -> 780 | K40: =+K10 -> 1458 | L40: =+L10 -> 0 | M40: =+M10 -> 0 | ... S40: =+S10 -> 866 | V40: =R40+P40+N40+L40+J40+H40+F40 -> 5189 | W40: =+V40*$E40 -> 3201353.6 | X40: =S40+Q40+O40+M40+K40+I40+G40 -> 4331.03 | Y40: =+X40*$E40 -> 2672029 | Z40: =Y40-W40 -> -529324.59
...

Sheet Sheet1
F1: Tender | G1: Design | H1: Tender | I1: Design | J1: Tender | K1: Design | L1: Tender | M1: Design | N1: Tender | O1: Design | P1: Tender | Q1: Design | R1: Tender | S1: Design | T1: Tender | U1: Design | V1: Tender | W1: Design | X1: Tender | Y1: Design | AB1: Design | AC1: Design | AD1: Design | AE1: Design | AF1: Design | AG1: Design | AH1: Design | AI1: Design | AJ1: Design
A2: Name of Item | D2: Unit | E2: Rate | F2: Injewada Mr @ RD 120 M | H2: Sarpewda Mr @ RD 1110 M | J2: Koka Mr 1 @ RD 3240 M | L2: Koka Mr 2 @ RD 4645 M | N2: Sonkund Mr @ RD 6030 M | P2: Palora Mr @ RD 6850 M | R2: Kesalwada Mr @ RD 8770 M | T2: Dudhara Minor @ RD 1300 m | V2: Total | W2: Total | X2: Total | Y2: Total | AB2: Injewada Mr @ RD 120 M | AC2: Sarpewda Mr @ RD 1110 M | AD2: Koka Mr 1 @ RD 3240 M | AE2: Koka Mr 2 @ RD 4645 M | AF2: Sonkund Mr @ RD 6030 M | AG2: Palora Mr @ RD 6850 M | AH2: Kesalwada Mr @ RD 8770 M | AI2: Dudhara Minor @ RD 1300 m | AJ2: Total
F3: Qty | G3: Qty | H3: Qty | I3: Qty | J3: Qty | K3: Qty | L3: Qty | M3: Qty | N3: Qty | O3: Qty | P3: Qty | Q3: Qty | R3: Qty | S3: Qty | T3: Qty | U3: Qty | V3: Qty | W3: Qty | X3: Cost | Y3: Cost | AB3: Amount | AC3: Amount | AD3: Amount | AE3: Amount | AF3: Amount | AG3: Amount | AH3: Amount | AI3: Amount | AJ3: Cost
A4: =+'Table 1'!A28:C28 -> ITEM NO :1A Excavation for deep trenches for laying rising | B4: =+'Table 1'!B28:D28 -> 0 | C4: =+'Table 1'!C28:E28 -> 0 | D4: =+'Table 1'!D28:F28 -> CUM | E4: =+'Table 1'!E28:G28 -> 158.5 | F4: =+'Table 1'!F28:H28 -> 11716.26 | G4: =+'Table 1'!G28:I28 -> 11513.82 | H4: =+'Table 1'!H28:J28 -> 2671.12 | ... Z4: =+'Table 1'!Z28:AB28 -> 724849.03 | AB4: =+E$4*G4 -> 1824940.5 | AC4: =+E4*I4 -> 489346.56 | AD4: =+E4*K4 -> 4960358.9 | AE4: =+E4*M4 -> 692079.16 | AF4: =+E4*O4 -> 1712597.3 | AG4: =+E4*Q4 -> 5327245.2 | AH4: =+E4*S4 -> 1255966.7 | AJ4: =SUM(AB4:AI4) -> 16262534 | AK4: =+'Table 1'!Y28 -> 16262534 | AL4: =+AK4-AJ4 -> 0
A5: =+'Table 1'!A29:C29 -> ITEM NO : 1B EXCAVATION FOR DEEP TRENCHES | B5: =+'Table 1'!B29:D29 -> 0 | C5: =+'Table 1'!C29:E29 -> 0 | D5: =+'Table 1'!D29:F29 -> CUM | E5: =+'Table 1'!E29:G29 -> 647.9 | F5: =+'Table 1'!F29:H29 -> 1301.81 | G5: =+'Table 1'!G29:I29 -> 1279.31 | H5: =+'Table 1'!H29:J29 -> 425.82 | ... Z5: =+'Table 1'!Z29:AB29 -> 302744.23 | AB5: =+E5*G5 -> 828864.95 | AC5: =+E5*I5 -> 318889.9 | AD5: =+E5*K5 -> 2252936.2 | AE5: =+E5*M5 -> 314328.68 | AF5: =+E5*O5 -> 777836.34 | AG5: =+E5*Q5 -> 2419569.6 | AH5: =+E5*S5 -> 818459.67 | AJ5: =SUM(AB5:AI5) -> 7730885.3 | AK5: =+'Table 1'!Y29 -> 7730885.3 | AL5: =+AK5-AJ5 -> 0
A6: =+'Table 1'!A30:C30 -> ITEM NO :2 EXCAVATION IN SOFT STARTA | B6: =+'Table 1'!B30:D30 -> 0 | C6: =+'Table 1'!C30:E30 -> 0 | D6: =+'Table 1'!D30:F30 -> CUM | E6: =+'Table 1'!E30:G30 -> 106 | F6: =+'Table 1'!F30:H30 -> 440.25 | G6: =+'Table 1'!G30:I30 -> 440.25 | H6: =+'Table 1'!H30:J30 -> 173.95 | ... Z6: =+'Table 1'!Z30:AB30 -> 0 | AB6: =+E6*G6 -> 46666.5 | AC6: =+E6*I6 -> 18438.7 | AD6: =+E6*K6 -> 114475.76 | AE6: =+E6*M6 -> 22589.66 | AF6: =+E6*O6 -> 61493.78 | AG6: =+E6*Q6 -> 201749.8 | AH6: =+E6*S6 -> 40661.6 | AJ6: =SUM(AB6:AI6) -> 506075.8 | AK6: =+'Table 1'!Y30 -> 506075.8 | AL6: =+AK6-AJ6 -> 0
A7: =+'Table 1'!A31:C31 -> ITEM NO :3 MURUM BEDDING | B7: =+'Table 1'!B31:D31 -> 0 | C7: =+'Table 1'!C31:E31 -> 0 | D7: =+'Table 1'!D31:F31 -> CUM | E7: =+'Table 1'!E31:G31 -> 242.9 | F7: =+'Table 1'!F31:H31 -> 1232.18 | G7: =+'Table 1'!G31:I31 -> 1162.29 | H7: =+'Table 1'!H31:J31 -> 291.06 | ... Z7: =+'Table 1'!Z31:AB31 -> 3242290.9 | AB7: =+E7*G7 -> 282320.24 | AC7: =+E7*I7 -> 83778.639 | AD7: =+E7*K7 -> 815439.59 | AE7: =+E7*M7 -> 131554.64 | AF7: =+E7*O7 -> 316639.58 | AG7: =+E7*Q7 -> 946984.51 | AH7: =+E7*S7 -> 3343947 | AJ7: =SUM(AB7:AI7) -> 5920664.2 | AK7: =+'Table 1'!Y31 -> 5920664.2 | AL7: =+AK7-AJ7 -> 0
A8: =+'Table 1'!A32:C32 -> ITEM NO : 4 BACKFILLING | B8: =+'Table 1'!B32:D32 -> 0 | C8: =+'Table 1'!C32:E32 -> 0 | D8: =+'Table 1'!D32:F32 -> CUM | E8: =+'Table 1'!E32:G32 -> 47.3 | F8: =+'Table 1'!F32:H32 -> 7454.7312 | G8: =+'Table 1'!G32:I32 -> 7315.9052 | H8: =+'Table 1'!H32:J32 -> 1751.4 | ... Z8: =+'Table 1'!Z32:AB32 -> 128003.2 | AB8: =+E8*G8 -> 346042.32 | AC8: =+E8*I8 -> 95142.531 | AD8: =+E8*K8 -> 899265.05 | AE8: =+E8*M8 -> 123134.53 | AF8: =+E8*O8 -> 306917.4 | AG8: =+E8*Q8 -> 957576.67 | AH8: =+E8*S8 -> 233271.89 | AJ8: =SUM(AB8:AI8) -> 2961350.4 | AK8: =+'Table 1'!Y32 -> 2961350.4 | AL8: =+AK8-AJ8 -> 0
A9: =+'Table 1'!A33:C33 -> ITEM NO :5 RUBBLE SOLLING BELOW | B9: =+'Table 1'!B33:D33 -> 0 | C9: =+'Table 1'!C33:E33 -> 0 | D9: =+'Table 1'!D33:F33 -> CUM | E9: =+'Table 1'!E33:G33 -> 1973 | F9: =+'Table 1'!F33:H33 -> 39.94 | G9: =+'Table 1'!G33:I33 -> 39.94 | H9: =+'Table 1'!H33:J33 -> 20.7 | ... Z9: =+'Table 1'!Z33:AB33 -> 0 | AB9: =+E9*G9 -> 78801.62 | AC9: =+E9*I9 -> 40841.1 | AD9: =+E9*K9 -> 193393.46 | AE9: =+E9*M9 -> 48812.02 | AF9: =+E9*O9 -> 115657.26 | AG9: =+E9*Q9 -> 338290.58 | AH9: =+E9*S9 -> 82037.34 | AJ9: =SUM(AB9:AI9) -> 897833.38 | AK9: =+'Table 1'!Y33 -> 897833.38 | AL9: =+AK9-AJ9 -> 0
A10: =+'Table 1'!A34:C34 -> ITEM NO :6 SAND BEDDING | B10: =+'Table 1'!B34:D34 -> 0 | C10: =+'Table 1'!C34:E34 -> 0 | D10: =+'Table 1'!D34:F34 -> CUM | E10: =+'Table 1'!E34:G34 -> 1276.25 | F10: =+'Table 1'!F34:H34 -> 364.4 | G10: =+'Table 1'!G34:I34 -> 343.14 | H10: =+'Table 1'!H34:J34 -> 98.51 | ... Z10: =+'Table 1'!Z34:AB34 -> 188387.26 | AB10: =+E10*G10 -> 437932.43 | AC10: =+E10*I10 -> 142914.48 | AD10: =+E10*K10 -> 1243756.7 | AE10: =+E10*M10 -> 213235.85 | AF10: =+E10*O10 -> 511686.91 | AG10: =+E10*Q10 -> 1521570.8 | AH10: =+E10*S10 -> 381420.08 | AJ10: =SUM(AB10:AI10) -> 4452517.2 | AK10: =+'Table 1'!Y34 -> 4452517.2 | AL10: =+AK10-AJ10 -> 0
A11: =+'Table 1'!A35:C35 -> 0 | B11: =+'Table 1'!B35:D35 -> 0 | C11: =+'Table 1'!C35:E35 -> 0 | D11: =+'Table 1'!D35:F35 -> 0 | E11: =+'Table 1'!E35:G35 -> 0 | F11: =+'Table 1'!F35:H35 -> 0 | G11: =+'Table 1'!G35:I35 -> 0 | H11: =+'Table 1'!H35:J35 -> 0 | ... Z11: =+'Table 1'!Z35:AB35 -> 0 | AB11: =+E11*G11 -> 0 | AC11: =+E11*I11 -> 0 | AD11: =+E11*K11 -> 0 | AE11: =+E11*M11 -> 0 | AF11: =+E11*O11 -> 0 | AG11: =+E11*Q11 -> 0 | AH11: =+E11*S11 -> 0 | AJ11: =SUM(AB11:AI11) -> 0 | AK11: =+'Table 1'!Y35 -> 0 | AL11: =+AK11-AJ11 -> 0
A12: =+'Table 1'!A36:C36 -> ITEM NO 7 | B12: =+'Table 1'!B36:D36 -> 0 | C12: =+'Table 1'!C36:E36 -> 0 | D12: =+'Table 1'!D36:F36 -> 0 | E12: =+'Table 1'!E36:G36 -> 0 | F12: =+'Table 1'!F36:H36 -> 0 | G12: =+'Table 1'!G36:I36 -> 0 | H12: =+'Table 1'!H36:J36 -> 0 | ... Z12: =+'Table 1'!Z36:AB36 -> 0 | AB12: =+E12*G12 -> 0 | AC12: =+E12*I12 -> 0 | AD12: =+E12*K12 -> 0 | AE12: =+E12*M12 -> 0 | AF12: =+E12*O12 -> 0 | AG12: =+E12*Q12 -> 0 | AH12: =+E12*S12 -> 0 | AJ12: =SUM(AB12:AI12) -> 0 | AK12: =+'Table 1'!Y36 -> 0 | AL12: =+AK12-AJ12 -> 0
A13: =+'Table 1'!A37:C37 -> 0 | B13: =+'Table 1'!B37:D37 -> 110 | C13: =+'Table 1'!C37:E37 -> mm | D13: =+'Table 1'!D37:F37 -> Rmt | E13: =+'Table 1'!E37:G37 -> 329.2 | F13: =+'Table 1'!F37:H37 -> 884 | G13: =+'Table 1'!G37:I37 -> 0 | H13: =+'Table 1'!H37:J37 -> 0 | ... Z13: =+'Table 1'!Z37:AB37 -> -359486.4 | AB13: =+E13*G13 -> 0 | AC13: =+E13*I13 -> 0 | AD13: =+E13*K13 -> 0 | AE13: =+E13*M13 -> 0 | AF13: =+E13*O13 -> 0 | AG13: =+E13*Q13 -> 0 | AH13: =+E13*S13 -> 0 | AJ13: =SUM(AB13:AI13) -> 0 | AK13: =+'Table 1'!Y37 -> 0 | AL13: =+AK13-AJ13 -> 0
A14: =+'Table 1'!A38:C38 -> 0 | B14: =+'Table 1'!B38:D38 -> 125 | C14: =+'Table 1'!C38:E38 -> mm | D14: =+'Table 1'!D38:F38 -> Rmt | E14: =+'Table 1'!E38:G38 -> 394.9 | F14: =+'Table 1'!F38:H38 -> 1542 | G14: =+'Table 1'!G38:I38 -> 0 | H14: =+'Table 1'!H38:J38 -> 0 | ... Z14: =+'Table 1'!Z38:AB38 -> -1831151.3 | AB14: =+E14*G14 -> 0 | AC14: =+E14*I14 -> 0 | AD14: =+E14*K14 -> 0 | AE14: =+E14*M14 -> 0 | AF14: =+E14*O14 -> 0 | AG14: =+E14*Q14 -> 0 | AH14: =+E14*S14 -> 0 | AJ14: =SUM(AB14:AI14) -> 0 | AK14: =+'Table 1'!Y38 -> 0 | AL14: =+AK14-AJ14 -> 0
A15: =+'Table 1'!A39:C39 -> 0 | B15: =+'Table 1'!B39:D39 -> 140 | C15: =+'Table 1'!C39:E39 -> mm | D15: =+'Table 1'!D39:F39 -> Rmt | E15: =+'Table 1'!E39:G39 -> 487.35 | F15: =+'Table 1'!F39:H39 -> 327 | G15: =+'Table 1'!G39:I39 -> 1291.3 | H15: =+'Table 1'!H39:J39 -> 476 | ... Z15: =+'Table 1'!Z39:AB39 -> 2934480.6 | AB15: =+E15*G15 -> 629315.06 | AC15: =+E15*I15 -> 592617.6 | AD15: =+E15*K15 -> 3318853.5 | AE15: =+E15*M15 -> 773424.45 | AF15: =+E15*O15 -> 1231533.4 | AG15: =+E15*Q15 -> 3505995.9 | AH15: =+E15*S15 -> 890388.45 | AJ15: =SUM(AB15:AI15) -> 10942128 | AK15: =+'Table 1'!Y39 -> 10942128 | AL15: =+AK15-AJ15 -> 0
A16: =+'Table 1'!A40:C40 -> 0 | B16: =+'Table 1'!B40:D40 -> 160 | C16: =+'Table 1'!C40:E40 -> mm | D16: =+'Table 1'!D40:F40 -> Rmt | E16: =+'Table 1'!E40:G40 -> 616.95 | F16: =+'Table 1'!F40:H40 -> 664 | G16: =+'Table 1'!G40:I40 -> 383.03 | H16: =+'Table 1'!H40:J40 -> 888 | ... Z16: =+'Table 1'!Z40:AB40 -> -529324.59 | AB16: =+E16*G16 -> 236310.36 | AC16: =+E16*I16 -> 0 | AD16: =+E16*K16 -> 899513.1 | AE16: =+E16*M16 -> 0 | AF16: =+E16*O16 -> 434949.75 | AG16: =+E16*Q16 -> 566977.05 | AH16: =+E16*S16 -> 534278.7 | AJ16: =SUM(AB16:AI16) -> 2672029 | AK16: =+'Table 1'!Y40 -> 2672029 | AL16: =+AK16-AJ16 -> 0
... A79: =+'Table 1'!A103:C103 -> e | B79: =+'Table 1'!B103:D103 -> 900 | C79: =+'Table 1'!C103:E103 -> mm | D79: =+'Table 1'!D103:F103 -> No | E79: =+'Table 1'!E103:G103 -> 715824 | F79: =+'Table 1'!F103:H103 -> 0 | G79: =+'Table 1'!G103:I103 -> 0 | H79: =+'Table 1'!H103:J103 -> 0 | ... Z79: =+'Table 1'!Z103:AB103 -> 0 | AB79: =+E79*G79 -> 0 | AC79: =+E79*I79 -> 0 | AD79: =+E79*K79 -> 715824 | AE79: =+E79*M79 -> 0 | AF79: =+E79*O79 -> 0 | AG79: =+E79*Q79 -> 715824 | AH79: =+E79*S79 -> 0 | AJ79: =SUM(AB79:AI79) -> 1431648 | AK79: =+'Table 1'!Y103 -> 1431648 | AL79: =+AK79-AJ79 -> 0
A80: =+'Table 1'!A104:C104 -> 0 | B80: =+'Table 1'!B104:D104 -> 1200 | C80: =+'Table 1'!C104:E104 -> mm | D80: =+'Table 1'!D104:F104 -> No | E80: =+'Table 1'!E104:G104 -> 523463.49 | F80: =+'Table 1'!F104:H104 -> 0 | G80: =+'Table 1'!G104:I104 -> 0 | H80: =+'Table 1'!H104:J104 -> 1 | ... Z80: =+'Table 1'!Z104:AB104 -> 0 | AB80: =+E80*G80 -> 0 | AC80: =+E80*I80 -> 0 | AD80: =+E80*K80 -> 0 | AE80: =+E80*M80 -> 0 | AF80: =+E80*O80 -> 0 | AG80: =+E80*Q80 -> 0 | AJ80: =SUM(AB80:AI80) -> 0 | AK80: =+'Table 1'!Y104 -> 0 | AL80: =+AK80-AJ80 -> 0
A81: =+'Table 1'!A105:C105 -> Item No. 22:- Manufacturing, providing and supplying tapers, "Y" connection with crotch plate, | B81: =+'Table 1'!B105:D105 -> 0 | C81: =+'Table 1'!C105:E105 -> 0 | D81: =+'Table 1'!D105:F105 -> kg | E81: =+'Table 1'!E105:G105 -> 107.75 | F81: =+'Table 1'!F105:H105 -> 0 | G81: =+'Table 1'!G105:I105 -> 0 | H81: =+'Table 1'!H105:J105 -> 2616.85 | ... Z81: =+'Table 1'!Z105:AB105 -> 0 | AB81: =+E81*G81 -> 0 | AC81: =+E81*I81 -> 281965.59 | AD81: =+E81*K81 -> 121821.07 | AE81: =+E81*M81 -> 277973.45 | AF81: =+E81*O81 -> 0 | AG81: =+E81*Q81 -> 119194.13 | AH81: =+E81*S81 -> 0 | AJ81: =SUM(AB81:AI81) -> 800954.24 | AK81: =+'Table 1'!Y105 -> 800954.24 | AL81: =+AK81-AJ81 -> 0
A82: =+'Table 1'!A106:C106 -> Item No. 23:- Hydraulic testing of H. D. P. E. pipe line to specified pressure including cost of all | B82: =+'Table 1'!B106:D106 -> 0 | C82: =+'Table 1'!C106:E106 -> 0 | D82: =+'Table 1'!D106:F106 -> 0 | E82: =+'Table 1'!E106:G106 -> 0 | F82: =+'Table 1'!F106:H106 -> 0 | G82: =+'Table 1'!G106:I106 -> 0 | H82: =+'Table 1'!H106:J106 -> 0 | ... Z82: =+'Table 1'!Z106:AB106 -> 0 | AB82: =+E82*G82 -> 0 | AC82: =+E82*I82 -> 0 | AD82: =+E82*K82 -> 0 | AE82: =+E82*M82 -> 0 | AF82: =+E82*O82 -> 0 | AG82: =+E82*Q82 -> 0 | AH82: =+E82*S82 -> 0 | AJ82: =SUM(AB82:AI82) -> 0 | AK82: =+'Table 1'!Y106 -> 0 | AL82: =+AK82-AJ82 -> 0
A83: =+'Table 1'!A107:C107 -> a | B83: =+'Table 1'!B107:D107 -> 110 | C83: =+'Table 1'!C107:E107 -> mm | D83: =+'Table 1'!D107:F107 -> Km | E83: =+'Table 1'!E107:G107 -> 7818.95 | F83: =+'Table 1'!F107:H107 -> 0.88 | G83: =+'Table 1'!G107:I107 -> 0 | H83: =+'Table 1'!H107:J107 -> 0 | ... Z83: =+'Table 1'!Z107:AB107 -> -8522.6555 | AB83: =+E83*G83 -> 0 | AC83: =+E83*I83 -> 0 | AD83: =+E83*K83 -> 0 | AE83: =+E83*M83 -> 0 | AF83: =+E83*O83 -> 0 | AG83: =+E83*Q83 -> 0 | AH83: =+E83*S83 -> 0 | AJ83: =SUM(AB83:AI83) -> 0 | AK83: =+'Table 1'!Y107 -> 0 | AL83: =+AK83-AJ83 -> 0
A84: =+'Table 1'!A108:C108 -> b | B84: =+'Table 1'!B108:D108 -> 125 | C84: =+'Table 1'!C108:E108 -> mm | D84: =+'Table 1'!D108:F108 -> Km | E84: =+'Table 1'!E108:G108 -> 8021.3 | F84: =+'Table 1'!F108:H108 -> 1.54 | G84: =+'Table 1'!G108:I108 -> 0 | H84: =+'Table 1'!H108:J108 -> 0 | ... Z84: =+'Table 1'!Z108:AB108 -> -36288.361 | AB84: =+E84*G84 -> 0 | AC84: =+E84*I84 -> 0 | AD84: =+E84*K84 -> 0 | AE84: =+E84*M84 -> 930.4708 | AF84: =+E84*O84 -> 0 | AG84: =+E84*Q84 -> 0 | AH84: =+E84*S84 -> 0 | AJ84: =SUM(AB84:AI84) -> 930.4708 | AK84: =+'Table 1'!Y108 -> 930.4708 | AL84: =+AK84-AJ84 -> 0
A85: =+'Table 1'!A109:C109 -> c | B85: =+'Table 1'!B109:D109 -> 140 | C85: =+'Table 1'!C109:E109 -> mm | D85: =+'Table 1'!D109:F109 -> Km | E85: =+'Table 1'!E109:G109 -> 8643.4 | F85: =+'Table 1'!F109:H109 -> 0.33 | G85: =+'Table 1'!G109:I109 -> 1.2913 | H85: =+'Table 1'!H109:J109 -> 0.48 | ... Z85: =+'Table 1'!Z109:AB109 -> 40963.666 | AB85: =+E85*G85 -> 11161.222 | AC85: =+E85*I85 -> 10717.816 | AD85: =+E85*K85 -> 52750.67 | AE85: =+E85*M85 -> 7165.3786 | AF85: =+E85*O85 -> 23242.103 | AG85: =+E85*Q85 -> 62318.914 | AH85: =+E85*S85 -> 15791.492 | AJ85: =SUM(AB85:AI85) -> 183147.6 | AK85: =+'Table 1'!Y109 -> 183147.6 | AL85: =+AK85-AJ85 -> 0
A86: =+'Table 1'!A110:C110 -> d | B86: =+'Table 1'!B110:D110 -> 160 | C86: =+'Table 1'!C110:E110 -> mm | D86: =+'Table 1'!D110:F110 -> Km | E86: =+'Table 1'!E110:G110 -> 8976.3 | F86: =+'Table 1'!F110:H110 -> 0.66 | G86: =+'Table 1'!G110:I110 -> 0.17269 | H86: =+'Table 1'!H110:J110 -> 0.89 | ... Z86: =+'Table 1'!Z110:AB110 -> -1044.0335 | AB86: =+E86*G86 -> 1550.1172 | AC86: =+E86*I86 -> 0 | AD86: =+E86*K86 -> 11283.209 | AE86: =+E86*M86 -> 5762.7846 | AF86: =+E86*O86 -> 6875.8458 | AG86: =+E86*Q86 -> 12207.768 | AH86: =+E86*S86 -> 7773.4758 | AJ86: =SUM(AB86:AI86) -> 45453.201 | AK86: =+'Table 1'!Y110 -> 45453.201 | AL86: =+AK86-AJ86 -> 0
A87: =+'Table 1'!A111:C111 -> e | B87: =+'Table 1'!B111:D111 -> 180 | C87: =+'Table 1'!C111:E111 -> mm | D87: =+'Table 1'!D111:F111 -> Km | E87: =+'Table 1'!E111:G111 -> 9348.1 | F87: =+'Table 1'!F111:H111 -> 1.04 | G87: =+'Table 1'!G111:I111 -> 1.06702 | H87: =+'Table 1'!H111:J111 -> 0.47 | ... Z87: =+'Table 1'!Z111:AB111 -> 14293.432 | AB87: =+E87*G87 -> 9974.6097 | AC87: =+E87*I87 -> 3365.316 | AD87: =+E87*K87 -> 13788.448 | AE87: =+E87*M87 -> 0 | AF87: =+E87*O87 -> 2122.0187 | AG87: =+E87*Q87 -> 18789.681 | AH87: =+E87*S87 -> 1869.62 | AJ87: =SUM(AB87:AI87) -> 49909.693 | AK87: =+'Table 1'!Y111 -> 49909.693 | AL87: =+AK87-AJ87 -> 0
A88: =+'Table 1'!A112:C112 -> f | B88: =+'Table 1'!B112:D112 -> 200 | C88: =+'Table 1'!C112:E112 -> mm | D88: =+'Table 1'!D112:F112 -> Km | E88: =+'Table 1'!E112:G112 -> 9758.65 | F88: =+'Table 1'!F112:H112 -> 0.84 | G88: =+'Table 1'!G112:I112 -> 0.17085 | H88: =+'Table 1'!H112:J112 -> 0 | ... Z88: =+'Table 1'!Z112:AB112 -> 14441.338 | AB88: =+E88*G88 -> 1667.2654 | AC88: =+E88*I88 -> 0 | AD88: =+E88*K88 -> 3630.2178 | AE88: =+E88*M88 -> 917.3131 | AF88: =+E88*O88 -> 12217.83 | AG88: =+E88*Q88 -> 9953.823 | AH88: =+E88*S88 -> 4498.7377 | AJ88: =SUM(AB88:AI88) -> 32885.187 | AK88: =+'Table 1'!Y112 -> 32885.187 | AL88: =+AK88-AJ88 -> 0
A89: =+'Table 1'!A113:C113 -> g | B89: =+'Table 1'!B113:D113 -> 225 | C89: =+'Table 1'!C113:E113 -> mm | D89: =+'Table 1'!D113:F113 -> Km | E89: =+'Table 1'!E113:G113 -> 10326.55 | F89: =+'Table 1'!F113:H113 -> 0.26 | G89: =+'Table 1'!G113:I113 -> 0.11435 | H89: =+'Table 1'!H113:J113 -> 0 | ... Z89: =+'Table 1'!Z113:AB113 -> 3070.5996 | AB89: =+E89*G89 -> 1180.841 | AC89: =+E89*I89 -> 929.3895 | AD89: =+E89*K89 -> 11844.553 | AE89: =+E89*M89 -> 0 | AF89: =+E89*O89 -> 5225.2343 | AG89: =+E89*Q89 -> 13114.718 | AH89: =+E89*S89 -> 0 | AJ89: =SUM(AB89:AI89) -> 32294.736 | AK89: =+'Table 1'!Y113 -> 32294.736 | AL89: =+AK89-AJ89 -> 0
A90: =+'Table 1'!A114:C114 -> h | B90: =+'Table 1'!B114:D114 -> 250 | C90: =+'Table 1'!C114:E114 -> mm | D90: =+'Table 1'!D114:F114 -> Km | E90: =+'Table 1'!E114:G114 -> 10955.1 | F90: =+'Table 1'!F114:H114 -> 0.18 | G90: =+'Table 1'!G114:I114 -> 0.98567 | H90: =+'Table 1'!H114:J114 -> 0 | ... Z90: =+'Table 1'!Z114:AB114 -> 15037.737 | AB90: =+E90*G90 -> 10798.113 | AC90: =+E90*I90 -> 5148.897 | AD90: =+E90*K90 -> 2322.4812 | AE90: =+E90*M90 -> 2311.5261 | AF90: =+E90*O90 -> 3450.8565 | AG90: =+E90*Q90 -> 4491.591 | AH90: =+E90*S90 -> 3275.5749 | AJ90: =SUM(AB90:AI90) -> 31799.04 | AK90: =+'Table 1'!Y114 -> 31799.04 | AL90: =+AK90-AJ90 -> 0
A91: =+'Table 1'!A115:C115 -> i | B91: =+'Table 1'!B115:D115 -> 280 | C91: =+'Table 1'!C115:E115 -> mm | D91: =+'Table 1'!D115:F115 -> Km | E91: =+'Table 1'!E115:G115 -> 11789.45 | F91: =+'Table 1'!F115:H115 -> 0.23 | G91: =+'Table 1'!G115:I115 -> 0.15609 | H91: =+'Table 1'!H115:J115 -> 0.31 | ... Z91: =+'Table 1'!Z115:AB115 -> -1661.2514 | AB91: =+E91*G91 -> 1840.2153 | AC91: =+E91*I91 -> 3654.7295 | AD91: =+E91*K91 -> 4574.3066 | AE91: =+E91*M91 -> 2735.1524 | AF91: =+E91*O91 -> 2664.4157 | AG91: =+E91*Q91 -> 8370.5095 | AH91: =+E91*S91 -> 2794.0997 | AJ91: =SUM(AB91:AI91) -> 26633.429 | AK91: =+'Table 1'!Y115 -> 26633.429 | AL91: =+AK91-AJ91 -> 0
A92: =+'Table 1'!A116:C116 -> j | B92: =+'Table 1'!B116:D116 -> 315 | C92: =+'Table 1'!C116:E116 -> mm | D92: =+'Table 1'!D116:F116 -> Km | E92: =+'Table 1'!E116:G116 -> 13646.9 | F92: =+'Table 1'!F116:H116 -> 0 | G92: =+'Table 1'!G116:I116 -> 0 | H92: =+'Table 1'!H116:J116 -> 0 | ... Z92: =+'Table 1'!Z116:AB116 -> -8734.016 | AB92: =+E92*G92 -> 0 | AC92: =+E92*I92 -> 0 | AD92: =+E92*K92 -> 4121.3638 | AE92: =+E92*M92 -> 2292.6792 | AF92: =+E92*O92 -> 0 | AG92: =+E92*Q92 -> 19105.66 | AH92: =+E92*S92 -> 0 | AJ92: =SUM(AB92:AI92) -> 25519.703 | AK92: =+'Table 1'!Y116 -> 25519.703 | AL92: =+AK92-AJ92 -> 0
... A115: =+'Table 1'!A139:C139 -> Item No. 36:-Providing assistance in collecting data for preparation of voter list from relevanat | B115: =+'Table 1'!B139:D139 -> 0 | C115: =+'Table 1'!C139:E139 -> 0 | D115: =+'Table 1'!D139:F139 -> Ha. CCA | E115: =+'Table 1'!E139:G139 -> 41.6 | F115: =+'Table 1'!F139:H139 -> 124.95 | G115: =+'Table 1'!G139:I139 -> 149.06 | H115: =+'Table 1'!H139:J139 -> 47.61 | ... Z115: =+'Table 1'!Z139:AB139 -> 15185.664 | AB115: =+E115*G115 -> 6200.896 | AC115: =+E115*I115 -> 2442.752 | AD115: =+E115*K115 -> 22045.92 | AE115: =+E115*M115 -> 3241.472 | AF115: =+E115*O115 -> 9255.584 | AG115: =+E115*Q115 -> 26476.736 | AH115: =+E115*S115 -> 6705.504 | AJ115: =SUM(AB115:AI115) -> 76368.864 | AK115: =+'Table 1'!Y139 -> 76368.864 | AL115: =+AK115-AJ115 -> 0
A116: =+'Table 1'!A140:C140 -> Item No. 37:-Five year operation maintenance, and repair and of pipe distribution network ,consists of | B116: =+'Table 1'!B140:D140 -> 0 | C116: =+'Table 1'!C140:E140 -> 0 | D116: =+'Table 1'!D140:F140 -> 0 | E116: =+'Table 1'!E140:G140 -> 0 | F116: =+'Table 1'!F140:H140 -> 0 | G116: =+'Table 1'!G140:I140 -> 0 | H116: =+'Table 1'!H140:J140 -> 0 | ... Z116: =+'Table 1'!Z140:AB140 -> 80367.998 | AB116: =+SUM(AB4:AB115)*0.004 -> 117530.42 | AC116: =+SUM(AC4:AC115)*0.004 -> 31964.69 | AD116: =+SUM(AD4:AD115)*0.004 -> 386679.9 | AE116: =+SUM(AE4:AE115)*0.004 -> 48596.769 | AF116: =+SUM(AF4:AF115)*0.004 -> 130910.63 | AG116: =+SUM(AG4:AG115)*0.004 -> 383397.21 | AH116: =+SUM(AH4:AH115)*0.004 -> 114794.63 | AJ116: =SUM(AB116:AI116) -> 1213874.2 | AK116: =+'Table 1'!Y140 -> 1213874.2 | AL116: =+AK116-AJ116 -> 0
A117: =+'Table 1'!A141:C141 -> 1 year | B117: =+'Table 1'!B141:D141 -> 0 | C117: =+'Table 1'!C141:E141 -> 0.40 % of cost of work | D117: =+'Table 1'!D141:F141 -> 0 | E117: =+'Table 1'!E141:G141 -> 1134362 | F117: =+'Table 1'!F141:H141 -> 0 | G117: =+'Table 1'!G141:I141 -> 0 | H117: =+'Table 1'!H141:J141 -> 0 | ... Z117: =+'Table 1'!Z141:AB141 -> 80367.998 | AB117: =+$AB116 -> 117530.42 | AC117: =+$AC116 -> 31964.69 | AD117: =+$AD116 -> 386679.9 | AE117: =+$AE116 -> 48596.769 | AF117: =+$AF116 -> 130910.63 | AG117: =+$AG116 -> 383397.21 | AH117: =+$AH116 -> 114794.63 | AJ117: =SUM(AB117:AI117) -> 1213874.2 | AK117: =+'Table 1'!Y141 -> 1213874.2 | AL117: =+AK117-AJ117 -> 0
A118: =+'Table 1'!A142:C142 -> 2 year | B118: =+'Table 1'!B142:D142 -> 0 | C118: =+'Table 1'!C142:E142 -> 0.40 % of cost of work | D118: =+'Table 1'!D142:F142 -> 0 | E118: =+'Table 1'!E142:G142 -> 1134362 | F118: =+'Table 1'!F142:H142 -> 0 | G118: =+'Table 1'!G142:I142 -> 0 | H118: =+'Table 1'!H142:J142 -> 0 | ... Z118: =+'Table 1'!Z142:AB142 -> 80367.998 | AB118: =+$AB117 -> 117530.42 | AC118: =+$AC117 -> 31964.69 | AD118: =+$AD117 -> 386679.9 | AE118: =+$AE117 -> 48596.769 | AF118: =+$AF117 -> 130910.63 | AG118: =+$AG117 -> 383397.21 | AH118: =+$AH117 -> 114794.63 | AJ118: =SUM(AB118:AI118) -> 1213874.2 | AK118: =+'Table 1'!Y142 -> 1213874.2 | AL118: =+AK118-AJ118 -> 0
A119: =+'Table 1'!A143:C143 -> 3 year | B119: =+'Table 1'!B143:D143 -> 0 | C119: =+'Table 1'!C143:E143 -> 0.40 % of cost of work | D119: =+'Table 1'!D143:F143 -> 0 | E119: =+'Table 1'!E143:G143 -> 1134362 | F119: =+'Table 1'!F143:H143 -> 0 | G119: =+'Table 1'!G143:I143 -> 0 | H119: =+'Table 1'!H143:J143 -> 0 | ... Z119: =+'Table 1'!Z143:AB143 -> 80367.998 | AB119: =+$AB118 -> 117530.42 | AC119: =+$AC118 -> 31964.69 | AD119: =+$AD118 -> 386679.9 | AE119: =+$AE118 -> 48596.769 | AF119: =+$AF118 -> 130910.63 | AG119: =+$AG118 -> 383397.21 | AH119: =+$AH118 -> 114794.63 | AJ119: =SUM(AB119:AI119) -> 1213874.2 | AK119: =+'Table 1'!Y143 -> 1213874.2 | AL119: =+AK119-AJ119 -> 0
A120: =+'Table 1'!A144:C144 -> 4 year | B120: =+'Table 1'!B144:D144 -> 0 | C120: =+'Table 1'!C144:E144 -> 0.40 % of cost of work | D120: =+'Table 1'!D144:F144 -> 0 | E120: =+'Table 1'!E144:G144 -> 1134362 | F120: =+'Table 1'!F144:H144 -> 0 | G120: =+'Table 1'!G144:I144 -> 0 | H120: =+'Table 1'!H144:J144 -> 0 | ... Z120: =+'Table 1'!Z144:AB144 -> 80367.998 | AB120: =+$AB119 -> 117530.42 | AC120: =+$AC119 -> 31964.69 | AD120: =+$AD119 -> 386679.9 | AE120: =+$AE119 -> 48596.769 | AF120: =+$AF119 -> 130910.63 | AG120: =+$AG119 -> 383397.21 | AH120: =+$AH119 -> 114794.63 | AJ120: =SUM(AB120:AI120) -> 1213874.2 | AK120: =+'Table 1'!Y144 -> 1213874.2 | AL120: =+AK120-AJ120 -> 0
A121: =+'Table 1'!A145:C145 -> 5 year | B121: =+'Table 1'!B145:D145 -> 0 | C121: =+'Table 1'!C145:E145 -> 0.40 % of cost of work | D121: =+'Table 1'!D145:F145 -> 0 | E121: =+'Table 1'!E145:G145 -> 1134362 | F121: =+'Table 1'!F145:H145 -> 0 | G121: =+'Table 1'!G145:I145 -> 0 | H121: =+'Table 1'!H145:J145 -> 0 | ... Z121: =+'Table 1'!Z145:AB145 -> 80367.998 | AB121: =+$AB120 -> 117530.42 | AC121: =+$AC120 -> 31964.69 | AD121: =+$AD120 -> 386679.9 | AE121: =+$AE120 -> 48596.769 | AF121: =+$AF120 -> 130910.63 | AG121: =+$AG120 -> 383397.21 | AH121: =+$AH120 -> 114794.63 | AJ121: =SUM(AB121:AI121) -> 1213874.2 | AK121: =+'Table 1'!Y145 -> 1213874.2 | AL121: =+AK121-AJ121 -> 0
A122: =+'Table 1'!A146:C146 -> 0 | B122: =+'Table 1'!B146:D146 -> 0 | C122: =+'Table 1'!C146:E146 -> 0 | D122: =+'Table 1'!D146:F146 -> 0 | E122: =+'Table 1'!E146:G146 -> 0 | F122: =+'Table 1'!F146:H146 -> 0 | G122: =+'Table 1'!G146:I146 -> 0 | H122: =+'Table 1'!H146:J146 -> 0 | ... Z122: =+'Table 1'!Z146:AB146 -> 0 | AB122: =SUM(AB4:AB121) -> 30087787 | AC122: =SUM(AC4:AC121) -> 8182960.7 | AD122: =SUM(AD4:AD121) -> 98990055 | AE122: =SUM(AE4:AE121) -> 12440773 | AF122: =SUM(AF4:AF121) -> 33513121 | AG122: =SUM(AG4:AG121) -> 98149686 | AH122: =SUM(AH4:AH121) -> 29387426 | AI122: =SUM(AI4:AI121) -> 0 | AJ122: =SUM(AJ4:AJ121) -> 3.1075181e+08 | AL122: =+AK122-AJ122 -> -3.1075181e+08
A123: =+'Table 1'!A147:C147 -> 0 | B123: =+'Table 1'!B147:D147 -> 0 | C123: =+'Table 1'!C147:E147 -> 0 | D123: =+'Table 1'!D147:F147 -> 0 | E123: =+'Table 1'!E147:G147 -> 0 | F123: =+'Table 1'!F147:H147 -> 0 | G123: =+'Table 1'!G147:I147 -> 0 | H123: =+'Table 1'!H147:J147 -> 0 | ... Z123: =+'Table 1'!Z147:AB147 -> 0 | AJ123: =+'Table 1'!Y146 -> 3.1075181e+08 | AL123: =+AK123-AJ123 -> -3.1075181e+08
AJ124: =+AJ123-AJ122 -> 0 | AL124: =+AK124-AJ124 -> 0
...

Sheet COMPARITIVE
A1: MINORS | B1: Tender | E1: Design | H1: DIFF
B2: =+'Table 1'!V5 -> 1470.75 | C2: CCA | D2: AMOUNT PER CCA | E2: =+'Table 1'!X5 -> 1812.39 | F2: CCA | G2: AMOUNT PER CCA
A3: Injewada Mr @ RD 120 M | B3: =+[10]Abstract!$H$137 -> 26797156 | C3: =+'Table 1'!F5 -> 124.95 | D3: =+B3/C3 -> 214463.03 | E3: =+[3]Abstract!$H$137 -> 29292474 | F3: =+'Table 1'!G5 -> 149.42 | G3: =+E3/F3 -> 196041.19 | H3: =+E3-B3 -> 2495318
A4: Sarpewda Mr @ RD 1110 M | B4: =+[11]Abstract!$H$136 -> 7050991 | C4: =+'Table 1'!H5 -> 47.611 | D4: =+B4/C4 -> 148095.84 | E4: =+[4]Abstract!$H$136 -> 7920550 | F4: =+'Table 1'!I5 -> 58.72 | G4: =+E4/F4 -> 134886.75 | H4: =+E4-B4 -> 869559
A5: Koka Mr 1 @ RD 3240 M | B5: =+[12]Abstract!$H$137 -> 100619832 | C5: =+'Table 1'!J5 -> 454.04 | D5: =+B5/C5 -> 221610.06 | E5: =+[5]Abstract!$H$137 -> 95180630 | F5: =+'Table 1'!K5 -> 530.14 | G5: =+E5/F5 -> 179538.67 | H5: =+E5-B5 -> -5439202
A6: Koka Mr 2 @ RD 4645 M | B6: =+[13]Abstract!$H$132 -> 11917084 | C6: =+'Table 1'!L5 -> 52.19 | D6: =+B6/C6 -> 228340.37 | E6: =+[6]Abstract!$H$132 -> 11890947 | F6: =+'Table 1'!M5 -> 77.92 | G6: =+E6/F6 -> 152604.56 | H6: =+E6-B6 -> -26137
A7: Sonkund Mr @ RD 6030 M | B7: =+[14]Abstract!$H$133 -> 31809007 | C7: =+'Table 1'!N5 -> 164.88 | D7: =+B7/C7 -> 192922.17 | E7: =+[7]Abstract!$H$133 -> 30191058 | F7: =+'Table 1'!O5 -> 221.79 | G7: =+E7/F7 -> 136124.52 | H7: =+E7-B7 -> -1617949
A8: Palora Mr @ RD 6850 M | B8: =+[15]Abstract!$H$133 -> 80359545 | C8: =+'Table 1'!P5 -> 493.502 | D8: =+B8/C8 -> 162835.3 | E8: =+[8]Abstract!$H$133 -> 94968184 | F8: =+'Table 1'!Q5 -> 612.33 | G8: =+E8/F8 -> 155093.14 | H8: =+E8-B8 -> 14608639
A9: Kesalwada Mr @ RD 8770 M | B9: =+[16]Abstract!$H$133 -> 30708741 | C9: =+'Table 1'!R5 -> 133.58 | D9: =+B9/C9 -> 229890.26 | E9: =+[9]Abstract!$H$133 -> 26500987 | F9: =+'Table 1'!S5 -> 162.07 | G9: =+E9/F9 -> 163515.68 | H9: =+E9-B9 -> -4207754
A10: TOTAL | B10: =SUM(B3:B9) -> 289262356 | C10: =SUM(C3:C9) -> 1470.753 | E10: =SUM(E3:E9) -> 295944830 | F10: =SUM(F3:F9) -> 1812.39 | H10: =+E10-B10 -> 6682474 | I10: =+B10/B2 -> 196676.77 | J10: =+E10/E2 -> 163289.82
F11: =+F10-C10 -> 341.637
B12: 289259871 | F12: =+F11/C10 -> 0.23228713 | H12: =+H10/B10 -> 0.023101775
B13: =+B10-B12 -> 2485
